Workbook

Sheet New Search
B1: G. Basin specific searches | C1: (AND) Headline and Lead | D1: Basin_Specific_Terms | E1: BCODE | F1: Basin_Name | G1: RA Name | H1: Has search been completed and all files downloaded? (Y (15 July 2022) if through that date, or Y if through 1 July 2023/N/Issues) >>leave filtered N | I1: Has search for 15 July 2022 - 1 July 2023 been completed and all files downloaded and excel consolidated? (N/Y/Not needed) | J1: Has preliminary review been completed through 1 July 2023? (Y/N/Issues) | K1: Has preliminary review for additional search year of 15 July 2022 - 1 July 2023 been completed? (Y/N/Not Needed) | L1: Search Notes, Identify any issues | M1: =COUNTIF(H2:H315,"Y (15 July 2022)") -> 178
B2: 1 | C2: (AND) Headline and Lead | D2: Adige | E2: ADIG | F2: Adige | G2: Raunaq | H2: Y (15 July 2022) | I2: Y | J2: Y (15 July 2022) | K2: Y
B3: 2 | C3: (AND) Headline and Lead | D3: Akpa | E3: AKPA | F3: Akpa | G3: Raunaq | H3: Y (15 July 2022) | I3: Y | J3: Y (15 July 2022) | K3: Y
B4: 3 | C4: (AND) Headline and Lead | D4: Alakol | E4: ALKL | F4: Alakol | G4: Raunaq | H4: Y (15 July 2022) | I4: Y | J4: Y (15 July 2022) | K4: Y
B5: 4 | C5: (AND) Headline and Lead | D5: Alsek OR Bates Lake | E5: ALSK | F5: Alsek | G5: Raunaq | H5: Y (15 July 2022) | I5: Y | J5: Y (15 July 2022) | K5: Y
B6: 5 | C6: (AND) Headline and Lead | D6: Amacuro | E6: AMCR | F6: Amacuro | G6: Raunaq | H6: Y (15 July 2022) | I6: Y | J6: Y (15 July 2022) | K6: Y
B7: 6 | C7: (AND) Headline and Lead | D7: Amur OR Emur OR Huma OR Muling OR Naoli OR Songhua OR Amagun OR Argun OR Bikin OR Bureya OR CAPS(Dep) OR Gazimur OR Gilyuy OR Ingoda OR Kur OR Onon OR Oz. Chukchagirskoye OR Oz. Khanka OR Oz. Udyl' OR Shilka OR CAPS(Tok) OR Urmi OR Ussuri OR Zeya | E7: AMUR | F7: Amur | G7: Raunaq | H7: N | I7: Not Needed | J7: N | K7: Not Needed | L7: More than 10k results
B8: 7 | C8: (AND) Headline and Lead | D8: Amazon OR Apere OR Baures OR Beni OR Guapore OR Guapore Itenex OR Lago de San Luis OR Lago Rogaua OR Madidi OR CAPS(Paragua) OR Rapulo OR San Martin OR San Miguel OR CAPS(Secure) OR Yata OR Abacaxis OR Abuna OR Acalau OR Acarai OR CAPS(Agua) Pceta OR Ajuana OR Alalau OR Anama OR Anaua OR Andma OR Apiaca OR Apiau OR Apidia OR Araca OR Araua OR Arinos OR Aripuana OR Arracias OR Arrairas OR Bacaja OR Bau OR Bia OR Brea OR Buriti OR Cach.Do Tareraimbu OR Cachoeir da Bateria OR Cachoeira Caracarai OR Cachoeira das Sete Quadas OR Cachoeira de Rebojo OR Cachoeira do Desatre OR Cachoeira do Pimena OR Cachoeira dos Indios OR Cachoeira Grande OR Cachoeira Ipada OR Cachoeira Ipanore OR Cachoeira Maranhao Grande OR Cachoeira Mergulhao OR Caluene OR Camanaa OR Camarure OR Canuma OR Capucapu OR Carabinuni OR Carajari OR Catete OR Catrimani OR Cauaburi OR Caures OR Cautario OR Chiche OR Coari OR Cotingo OR Crarari OR Crepori OR Cuiaba OR Cuiani OR Culiseu OR Cura do Sal OR Curicariari OR Curiuau OR Curu OR Curua OR Curua Una OR Curuaes OR Curuca OR Daraa OR Demini OR Demiti OR Do Paulo OR Embari OR Embira OR Fagundes OR CAPS(Ferro) OR CAPS(Fresco) OR Gregorio OR CAPS(Ia) OR CAPS(Ica) OR Igara Parana OR Imabu OR Infari OR Ipixuna OR Iriri OR Iriri Novo OR Itacuai OR Itari OR Itata OR Itaxi OR Itiguira OR Jaa OR Jamanxim OR Jamari OR Jandiatuba OR Japura OR Jaraucu OR Jari OR Jaru OR Jatapa OR Jatoba OR Jau OR Jauaperi OR Jiparana OR Jotoba OR Juina OR Jurua OR Juruena OR Jutai OR Uberaba OR de Sapucua OR do Erepeca OR Gaibo OR Grande de Manacapuru OR Mandiore OR Lago Canacari OR Liberdade OR Madeira OR Madeirinha OR Maicara OR Majari OR Mamore OR Manicana Micu OR Manso OR Mapuera OR Marapi OR Marauia OR Marie OR Maues OR Moaco OR Mucajai OR Mucucuau OR Nhamunda OR Nivo OR Padauiri OR Papagaio OR CAPS(Para) OR Paranarta OR Pareis OR Paru de Oeste OR Pauini OR CAPS(Paz) OR Peixes OR Peixoto de Azevedo OR Pinhua OR Piratucu OR Preto OR CAPS(Puras) OR Purue OR Purus OR Riozinho OR Ronuro OR Rpresa da Balbina OR Sacuriuina OR Salao OR Sangue OR Sao Benedito OR Sao Lourenco OR Sao Tume OR Sauenina OR Saueruina OR Solimooes OR Soterio OR Steinen OR Sucanduri OR Suir Micu OR Suluene OR Suramu OR Surumu OR Tamitatoula OR Batovi OR Tanguro OR Tapajos OR Tapaua OR Tapera OR Taruaca OR Tauini OR CAPS(Tea) OR Tefe OR Teles Pires OR Sao Manuel OR Theodore Roosevelt OR Tocantins OR CAPS(Triunfo) OR Uatuma OR Uneiaxi OR Unini OR Uraca OR Uraricoera OR Uruba OR Urubaxi OR CAPS(Verde) OR Vveni OR Xeriuini OR Xie OR Xingu OR Xirua OR Yavare OR Ajaju OR Apaporis OR Caqueta OR Cuduyari OR Icana OR Isasna OR Papuri OR Quainia OR Raudal Yupurari OR Devil's Cataract OR Tiquie OR Traira OR Uaupes OR Yari OR Curaray OR Morona OR Cafuini OR Ireng OR Tacutu OR CAPS(Acre) OR Allto Purus OR Apurimac OR CAPS(Blanco) OR Chandless OR CAPS(Chili) OR Correntes OR Heath OR Huallaga OR Iaco OR Inambari OR Inuya OR Jarua OR Manu Madre de Dios OR Manuripi OR Maranon OR Moranon OR Napo OR Orton OR Pachitea OR Pampas OR Postaza OR Putumayo OR San Juan OR Santa Ana OR Santa Eulalia OR Santuario OR Sheshea OR Tamuya OR Tapiche OR CAPS(Tigre) OR Ucayali OR Urabamba OR Yavari OR Trombetas OR Biria OR Casiquiare OR Concorochite OR CAPS(Grande) OR CAPS(Negro) | E8: AMZN | F8: Amazon | G8: Molly | H8: N | I8: Not Needed | J8: N | K8: Not Needed | L8: More than 10k results
B9: 8 | C9: (AND) Headline and Lead | D9: An Nahr Al Kabir OR Nahr Ibrahim | E9: ANAK | F9: An Nahr Al Kabir | G9: Raunaq | H9: Y (15 July 2022) | I9: Y | J9: Y (15 July 2022) | K9: Y
B10: 9 | C10: (AND) Headline and Lead | D10: Angerman | E10: ANGE | F10: Angerman | G10: Raunaq | H10: Y (15 July 2022) | I10: Y | J10: Y (15 July 2022) | K10: Y
B11: 10 | C11: (AND) Headline and Lead | D11: Annole | E11: ANNL | F11: Annole | G11: Rachel | H11: N | I11: Not Needed | J11: N | K11: Not Needed | L11: No Results
B12: 11 | C12: (AND) Headline and Lead | D12: Aral OR Syr Daria OR Naryn OR Amu Daria OR Syr Darya OR Amu Darya OR Akhangaran OR Chirchik | E12: ARAL | F12: Aral Sea | G12: Molly | H12: Y (15 July 2022) | I12: Y | J12: Y | K12: Y
B13: 12 | C13: (AND) Headline and Lead | D13: Asi OR Orontes OR Amik Golu | E13: ASIX | F13: Asi/Orontes | G13: Molly | H13: Y (15 July 2022) | I13: Y | J13: N | K13: N
B14: 13 | C14: (AND) Headline and Lead | D14: Artibonite OR Depeligre | E14: ATBN | F14: Artibonite | G14: Raunaq | H14: Y (15 July 2022) | I14: Y | J14: Y (15 July 2022) | K14: N
B15: 14 | C15: (AND) Headline and Lead | D15: Astara Chay | E15: ATCY | F15: Astara Chay | G15: Raunaq | H15: Y (15 July 2022) | I15: Y | J15: Y (15 July 2022) | K15: N
B16: 15 | C16: (AND) Headline and Lead | D16: Atrak OR Sumber | E16: ATRK | F16: Atrak | G16: Raunaq | H16: Y (15 July 2022) | I16: Y | J16: Y (15 July 2022) | K16: N
B17: 16 | C17: (AND) Headline and Lead | D17: Aviles | E17: AVLS | F17: Aviles | G17: Raunaq | H17: Y (15 July 2022) | I17: Y | J17: Y (15 July 2022) | K17: N
B18: 17 | C18: (AND) Headline and Lead | D18: Abhe Bid Hayak OR Awash OR Finochaa OR Gemeri Hayak OR Petit Akabi OR Sendafa | E18: AWSH | F18: Awash | G18: Molly | H18: Y (15 July 2022) | I18: Y | J18: N | K18: N
B19: 18 | C19: (AND) Headline and Lead | D19: Aysen | E19: AYSN | F19: Aysen | G19: Raunaq | H19: Y (15 July 2022) | I19: Y | J19: Y (15 July 2022) | K19: N
B20: 19 | C20: (AND) Headline and Lead | D20: Baker OR Cochrane | E20: BAKR | F20: Baker | G20: Raunaq | H20: N | I20: Not Needed | J20: N | K20: Not Needed | L20: More than 10k results
B21: 20 | C21: (AND) Headline and Lead | D21: Bann OR CAPS(Black Water) OR Laugh Neagh OR CAPS(Lower Laugh) Erine | E21: BANN | F21: Bann | G21: Molly | H21: Y | I21: Not Needed | J21: N | K21: Not Needed
B22: 21 | C22: (AND) Headline and Lead | D22: Bahr at Tubat | E22: BATU | F22: Bahr at Tubat | G22: Raunaq | H22: Y (15 July 2022) | I22: Y | J22: Y (15 July 2022) | K22: N
B23: 22 | C23: (AND) Headline and Lead | D23: Bidasoa | E23: BDSO | F23: Bidasoa | G23: Raunaq | H23: Y (15 July 2022) | I23: Y | J23: Y (15 July 2022) | K23: N
B24: 23 | C24: (AND) Headline and Lead | D24: Benito OR Ntem | E24: BENT | F24: Benito/Ntem | G24: Raunaq | H24: N | I24: Not Needed | J24: N | K24: Not Needed
B25: 24 | C25: (AND) Headline and Lead | D25: Bia | E25: BIAX | F25: Bia | G25: Molly | H25: Y (15 July 2022) | I25: Y | J25: N | K25: N
B26: 25 | C26: (AND) Headline and Lead | D26: Beilun | E26: BLUN | F26: Beilun | G26: Raunaq | H26: Y (15 July 2022) | I26: Y | J26: Y (15 July 2022) | K26: N
B27: 26 | C27: (AND) Headline and Lead | D27: Belize OR Mopan | E27: BLZE | F27: Belize | G27: Molly | H27: Y | I27: Not Needed | J27: N | K27: Not Needed
B28: 27 | C28: (AND) Headline and Lead | D28: Bangau | E28: BNGU | F28: Bangau | G28: Raunaq | H28: Y (15 July 2022) | I28: Y | J28: Y (15 July 2022) | K28: N
B29: 28 | C29: (AND) Headline and Lead | D29: Oued Bou Namoussa | E29: BNSA | F29: Oued Bou Namoussa | G29: Raunaq | H29: Y (15 July 2022) | I29: Y | J29: Y (15 July 2022) | K29: N
B30: 29 | C30: (AND) Headline and Lead | D30: Berbyelva | E30: BRBY | F30: Berbyelva | G30: Raunaq | H30: Y (15 July 2022) | I30: Y | J30: N | K30: N | L30: No results
B31: 30 | C31: (AND) Headline and Lead | D31: Baraka | E31: BRKA | F31: Baraka | G31: Raunaq | H31: Y (15 July 2022) | I31: Y | J31: N | K31: N
B32: 31 | C32: (AND) Headline and Lead | D32: Barima | E32: BRMA | F32: Barima | G32: Raunaq | H32: Y (15 July 2022) | I32: Y | J32: N | K32: N
B33: 32 | C33: (AND) Headline and Lead | D33: Barta | E33: BRTA | F33: Barta | G33: Raunaq | H33: Y (15 July 2022) | I33: Y | J33: N | K33: N
B34: 33 | C34: (AND) Headline and Lead | D34: Buzi OR Rio Revue OR Chibudzana OR Nyanhombo OR CAPS(Rio) OR Sterkstroom | E34: BUZI | F34: Buzi | G34: Molly | H34: N | I34: Not Needed | J34: N | K34: Not Needed | L34: More than 10k results
B35: 34 | C35: (AND) Headline and Lead | D35: Caetani | E35: CAET | F35: Caetani | G35: Raunaq | H35: Y (15 July 2022) | I35: Y | J35: N | K35: N
B36: 35 | C36: (AND) Headline and Lead | D36: Ca OR Song Lam | E36: CAXX | F36: Ca/Song Lam | G36: Raunaq | H36: N | I36: Not Needed | J36: N | K36: Not Needed | L36: More than 10k results
B37: 36 | C37: (AND) Headline and Lead | D37: Candelaria | E37: CDLR | F37: Candelaria | G37: Raunaq | H37: Y (15 July 2022) | I37: Y | J37: N | K37: N
B38: 37 | C38: (AND) Headline and Lead | D38: Changuinola | E38: CGNL | F38: Changuinola | G38: Raunaq | H38: Y (15 July 2022) | I38: Y | J38: N | K38: N
B39: 38 | C39: (AND) Headline and Lead | D39: Carmen Silva OR Chico | E39: CHIC | F39: Carmen Silva/Chico | G39: Raunaq | H39: Y (15 July 2022) | I39: Y | J39: N | K39: N
B40: 39 | C40: (AND) Headline and Lead | D40: Chira | E40: CHIR | F40: Chira | G40: Raunaq | H40: Y (15 July 2022) | I40: Y | J40: N | K40: N
...

Sheet Automation Prepping
A1: BCODE | B1: Basin_Name | C1: RA Name | D1: Has search been completed and all files downloaded? (Y (15 July 2022) if through that date, or Y if through 1 July 2023/N/Issues) >>leave filtered N | E1: Additional Status Sheet Needs Either (1 July 2023 - 15 March 2024) or (15 July 2022 - 15 March 2024) | F1: Has the process sheet for the Excel download been completed? (Need Add to 2024/Y if sheet through 15 March 2024)/in progress) Index (start at 0), basin name, start and end date - the rest can be left blank) | G1: File Name (BCODE_excel.xlsx) (paste in the Automation >> Status Sheets Folder) | H1: Has the process sheet been completed for the pdf download? (Y/N/in progress) | I1: Paste the URL of the Full Search
A2: ADIG | B2: Adige | D2: Y (1 July 2023) | E2: 1 July 2023 - 15 March 2024 | F2: Y | G2: ADIG_excel.xlsx | H2: Y | I2: https://advance-lexis-com.ezproxy.library.tufts.edu/search/?pdmfid=1516831&crid=fec62cbd-b7b8-4d21-88a4-2032ad75d6b3&pdpsf=&pdpost=&pdstartin=urn%3Ahlct%3A16&pdsearchterms=hlead(*water*+OR+river*+OR+lake+OR+dam+OR+stream+OR+tributary+OR+diversion+OR+irrigation+OR+pollution+OR+water+quality+OR+flood!+OR+drought!+OR+channel+OR+canal+OR+hydroelect!+OR+reservoir+OR+groundwater+OR+aquifer+OR+drought+OR+recharge+OR+%22water+table%22+OR+%22bore+hole%22)+and+hlead(treaty+OR+agree!+OR+negotiat!+OR+resolution+OR+commission+OR+secretariat+OR+joint+management+OR+basin+management+OR+peace+OR+accord+OR+%22peace+accord%22+OR+settle!+OR+cooperat!+OR+collaborat!+OR+disput!+OR+conflict!+OR+disagree!+OR+sanction!+OR+war+OR+troops+OR+%22letter+of+protest%22+OR+hostility+OR+%22shots+fired%22+OR+boycott+OR+protest!+OR+appeal+OR+intent+OR+reject+OR+threat!+OR+force+OR+coerce+OR+assault+OR+fight+OR+demand+OR+disapprove+OR+diploma!+OR+statement+OR+memorandum)+and+hlead(Adige)+and+not+hlead(ocean+OR+navigat!+OR+nuclear+OR+%22water+cannon%22+OR+%22light+water+reactor%22+OR+%22mineral+water%22+OR+%22hold+water%22+OR+%22cold+water%22+OR+%22hot+water%22+OR+%22water+canister%22+OR+%22water+tight%22+OR+%22+water+down%22+OR+%22flood+of+refugees%22+OR+Rivera+OR+Suez+OR+Panama+OR+oil+OR+drugs+OR+%22three+gorges%22+OR+waterski+OR+watermelon+OR+dishwater+OR+waterproof+OR+%22water+resistant%22+OR+%22water+bath%22+)&pdsearchtype=SearchBox&pdtypeofsearch=searchboxclick&pdsf=&pdquerytemplateid=&pdtimeline=undefined%7Calldates&pdfromadvancedsearchpage=true&ecomp=xxLg9kk&earg=pdpsf&prid=3e153b8f-e851-4639-9031-01a881cfdb32
A3: AKPA | B3: Akpa | C3: Raunaq | D3: Y (1 July 2023) | E3: 1 July 2023 - 15 March 2024 | F3: Y | G3: AKPA_excel.xlsx | H3: Y | I3: https://advance-lexis-com.ezproxy.library.tufts.edu/search/?pdmfid=1516831&crid=57793ffd-53d5-4693-8e20-0f0093f74143&pdpsf=&pdpost=&pdstartin=urn%3Ahlct%3A16&pdsearchterms=hlead(*water*+OR+river*+OR+lake+OR+dam+OR+stream+OR+tributary+OR+diversion+OR+irrigation+OR+pollution+OR+water+quality+OR+flood!+OR+drought!+OR+channel+OR+canal+OR+hydroelect!+OR+reservoir+OR+groundwater+OR+aquifer+OR+drought+OR+recharge+OR+%22water+table%22+OR+%22bore+hole%22)+and+hlead(treaty+OR+agree!+OR+negotiat!+OR+resolution+OR+commission+OR+secretariat+OR+joint+management+OR+basin+management+OR+peace+OR+accord+OR+%22peace+accord%22+OR+settle!+OR+cooperat!+OR+collaborat!+OR+disput!+OR+conflict!+OR+disagree!+OR+sanction!+OR+war+OR+troops+OR+%22letter+of+protest%22+OR+hostility+OR+%22shots+fired%22+OR+boycott+OR+protest!+OR+appeal+OR+intent+OR+reject+OR+threat!+OR+force+OR+coerce+OR+assault+OR+fight+OR+demand+OR+disapprove+OR+diploma!+OR+statement+OR+memorandum)+and+hlead(Akpa)+and+not+hlead(ocean+OR+navigat!+OR+nuclear+OR+%22water+cannon%22+OR+%22light+water+reactor%22+OR+%22mineral+water%22+OR+%22hold+water%22+OR+%22cold+water%22+OR+%22hot+water%22+OR+%22water+canister%22+OR+%22water+tight%22+OR+%22+water+down%22+OR+%22flood+of+refugees%22+OR+Rivera+OR+Suez+OR+Panama+OR+oil+OR+drugs+OR+%22three+gorges%22+OR+waterski+OR+watermelon+OR+dishwater+OR+waterproof+OR+%22water+resistant%22+OR+%22water+bath%22+)&pdsearchtype=SearchBox&pdtypeofsearch=searchboxclick&pdsf=&pdquerytemplateid=&pdtimeline=undefined%7Calldates&pdfromadvancedsearchpage=true&ecomp=xxLg9kk&earg=pdpsf&prid=3e153b8f-e851-4639-9031-01a881cfdb32
A4: ALKL | B4: Alakol | C4: Raunaq | D4: Y (1 July 2023) | E4: 1 July 2023 - 15 March 2024 | F4: Y | G4: ALKL_excel.xlsx | H4: Y | I4: https://advance-lexis-com.ezproxy.library.tufts.edu/search/?pdmfid=1516831&crid=70807c1d-644d-4515-8945-8dcc70ca15bd&pdpsf=&pdpost=&pdstartin=urn%3Ahlct%3A16&pdsearchterms=hlead(*water*+OR+river*+OR+lake+OR+dam+OR+stream+OR+tributary+OR+diversion+OR+irrigation+OR+pollution+OR+water+quality+OR+flood!+OR+drought!+OR+channel+OR+canal+OR+hydroelect!+OR+reservoir+OR+groundwater+OR+aquifer+OR+drought+OR+recharge+OR+%22water+table%22+OR+%22bore+hole%22)+and+hlead(treaty+OR+agree!+OR+negotiat!+OR+resolution+OR+commission+OR+secretariat+OR+joint+management+OR+basin+management+OR+peace+OR+accord+OR+%22peace+accord%22+OR+settle!+OR+cooperat!+OR+collaborat!+OR+disput!+OR+conflict!+OR+disagree!+OR+sanction!+OR+war+OR+troops+OR+%22letter+of+protest%22+OR+hostility+OR+%22shots+fired%22+OR+boycott+OR+protest!+OR+appeal+OR+intent+OR+reject+OR+threat!+OR+force+OR+coerce+OR+assault+OR+fight+OR+demand+OR+disapprove+OR+diploma!+OR+statement+OR+memorandum)+and+hlead(Alakol)+and+not+hlead(ocean+OR+navigat!+OR+nuclear+OR+%22water+cannon%22+OR+%22light+water+reactor%22+OR+%22mineral+water%22+OR+%22hold+water%22+OR+%22cold+water%22+OR+%22hot+water%22+OR+%22water+canister%22+OR+%22water+tight%22+OR+%22+water+down%22+OR+%22flood+of+refugees%22+OR+Rivera+OR+Suez+OR+Panama+OR+oil+OR+drugs+OR+%22three+gorges%22+OR+waterski+OR+watermelon+OR+dishwater+OR+waterproof+OR+%22water+resistant%22+OR+%22water+bath%22+)&pdsearchtype=SearchBox&pdtypeofsearch=searchboxclick&pdsf=&pdquerytemplateid=&pdtimeline=undefined%7Calldates&pdfromadvancedsearchpage=true&ecomp=xxLg9kk&earg=pdpsf&prid=3e153b8f-e851-4639-9031-01a881cfdb32
A5: ALSK | B5: Alsek | C5: Raunaq | D5: Y (1 July 2023) | E5: 1 July 2023 - 15 March 2024 | F5: Y | G5: ALSK_excel.xlsx | H5: Y | I5: https://advance-lexis-com.ezproxy.library.tufts.edu/search/?pdmfid=1516831&crid=2d355827-c7a2-4149-981f-5a23811f1279&pdpsf=&pdpost=&pdstartin=urn%3Ahlct%3A16&pdsearchterms=hlead(*water*+OR+river*+OR+lake+OR+dam+OR+stream+OR+tributary+OR+diversion+OR+irrigation+OR+pollution+OR+water+quality+OR+flood!+OR+drought!+OR+channel+OR+canal+OR+hydroelect!+OR+reservoir+OR+groundwater+OR+aquifer+OR+drought+OR+recharge+OR+%22water+table%22+OR+%22bore+hole%22)+and+hlead(treaty+OR+agree!+OR+negotiat!+OR+resolution+OR+commission+OR+secretariat+OR+joint+management+OR+basin+management+OR+peace+OR+accord+OR+%22peace+accord%22+OR+settle!+OR+cooperat!+OR+collaborat!+OR+disput!+OR+conflict!+OR+disagree!+OR+sanction!+OR+war+OR+troops+OR+%22letter+of+protest%22+OR+hostility+OR+%22shots+fired%22+OR+boycott+OR+protest!+OR+appeal+OR+intent+OR+reject+OR+threat!+OR+force+OR+coerce+OR+assault+OR+fight+OR+demand+OR+disapprove+OR+diploma!+OR+statement+OR+memorandum)+and+hlead(Alsek+OR+Bates+Lake)+and+not+hlead(ocean+OR+navigat!+OR+nuclear+OR+%22water+cannon%22+OR+%22light+water+reactor%22+OR+%22mineral+water%22+OR+%22hold+water%22+OR+%22cold+water%22+OR+%22hot+water%22+OR+%22water+canister%22+OR+%22water+tight%22+OR+%22+water+down%22+OR+%22flood+of+refugees%22+OR+Rivera+OR+Suez+OR+Panama+OR+oil+OR+drugs+OR+%22three+gorges%22+OR+waterski+OR+watermelon+OR+dishwater+OR+waterproof+OR+%22water+resistant%22+OR+%22water+bath%22+)&pdsearchtype=SearchBox&pdtypeofsearch=searchboxclick&pdsf=&pdquerytemplateid=&pdtimeline=undefined%7Calldates&pdfromadvancedsearchpage=true&ecomp=xxLg9kk&earg=pdpsf&prid=3e153b8f-e851-4639-9031-01a881cfdb32
A6: AMCR | B6: Amacuro | C6: Raunaq | D6: Y (1 July 2023) | E6: 1 July 2023 - 15 March 2024 | F6: Y | G6: AMCR_excel.xlsx | H6: Y | I6: https://advance-lexis-com.ezproxy.library.tufts.edu/search/?pdmfid=1516831&crid=f527046e-bb0e-4f82-9a1a-3d513f064c56&pdpsf=&pdpost=&pdstartin=urn%3Ahlct%3A16&pdsearchterms=hlead(*water*+OR+river*+OR+lake+OR+dam+OR+stream+OR+tributary+OR+diversion+OR+irrigation+OR+pollution+OR+water+quality+OR+flood!+OR+drought!+OR+channel+OR+canal+OR+hydroelect!+OR+reservoir+OR+groundwater+OR+aquifer+OR+drought+OR+recharge+OR+%22water+table%22+OR+%22bore+hole%22)+and+hlead(treaty+OR+agree!+OR+negotiat!+OR+resolution+OR+commission+OR+secretariat+OR+joint+management+OR+basin+management+OR+peace+OR+accord+OR+%22peace+accord%22+OR+settle!+OR+cooperat!+OR+collaborat!+OR+disput!+OR+conflict!+OR+disagree!+OR+sanction!+OR+war+OR+troops+OR+%22letter+of+protest%22+OR+hostility+OR+%22shots+fired%22+OR+boycott+OR+protest!+OR+appeal+OR+intent+OR+reject+OR+threat!+OR+force+OR+coerce+OR+assault+OR+fight+OR+demand+OR+disapprove+OR+diploma!+OR+statement+OR+memorandum)+and+hlead(Amacuro)+and+not+hlead(ocean+OR+navigat!+OR+nuclear+OR+%22water+cannon%22+OR+%22light+water+reactor%22+OR+%22mineral+water%22+OR+%22hold+water%22+OR+%22cold+water%22+OR+%22hot+water%22+OR+%22water+canister%22+OR+%22water+tight%22+OR+%22+water+down%22+OR+%22flood+of+refugees%22+OR+Rivera+OR+Suez+OR+Panama+OR+oil+OR+drugs+OR+%22three+gorges%22+OR+waterski+OR+watermelon+OR+dishwater+OR+waterproof+OR+%22water+resistant%22+OR+%22water+bath%22+)&pdsearchtype=SearchBox&pdtypeofsearch=searchboxclick&pdsf=&pdquerytemplateid=&pdtimeline=undefined%7Calldates&pdfromadvancedsearchpage=true&ecomp=xxLg9kk&earg=pdpsf&prid=3e153b8f-e851-4639-9031-01a881cfdb32
A7: AMUR | B7: Amur | C7: Raunaq | D7: N | E7: Update Sheet to 15 March 2024 | F7: Need Add to 2024 | G7: AMUR_excel.xlsx | I7: https://advance-lexis-com.ezproxy.library.tufts.edu/search/?pdmfid=1516831&crid=86bbb8d1-9f00-481b-bfc5-ec60245e8070&pdpsf=&pdpost=&pdstartin=urn%3Ahlct%3A16&pdsearchterms=hlead(*water*+OR+river*+OR+lake+OR+dam+OR+stream+OR+tributary+OR+diversion+OR+irrigation+OR+pollution+OR+water+quality+OR+flood!+OR+drought!+OR+channel+OR+canal+OR+hydroelect!+OR+reservoir+OR+groundwater+OR+aquifer+OR+drought+OR+recharge+OR+%22water+table%22+OR+%22bore+hole%22)+and+hlead(treaty+OR+agree!+OR+negotiat!+OR+resolution+OR+commission+OR+secretariat+OR+joint+management+OR+basin+management+OR+peace+OR+accord+OR+%22peace+accord%22+OR+settle!+OR+cooperat!+OR+collaborat!+OR+disput!+OR+conflict!+OR+disagree!+OR+sanction!+OR+war+OR+troops+OR+%22letter+of+protest%22+OR+hostility+OR+%22shots+fired%22+OR+boycott+OR+protest!+OR+appeal+OR+intent+OR+reject+OR+threat!+OR+force+OR+coerce+OR+assault+OR+fight+OR+demand+OR+disapprove+OR+diploma!+OR+statement+OR+memorandum)+and+hlead(Amur+OR+Emur+OR+Huma+OR+Muling+OR+Naoli+OR+Songhua+OR+Amagun+OR+Argun+OR+Bikin+OR+Bureya+OR+CAPS(Dep)+OR+Gazimur+OR+Gilyuy+OR+Ingoda+OR+Kur+OR+Onon+OR+Oz.+Chukchagirskoye+OR+Oz.+Khanka+OR+Oz.+Udyl%27+OR+Shilka+OR+CAPS(Tok)+OR+Urmi+OR+Ussuri+OR+Zeya)+and+not+hlead(ocean+OR+navigat!+OR+nuclear+OR+%22water+cannon%22+OR+%22light+water+reactor%22+OR+%22mineral+water%22+OR+%22hold+water%22+OR+%22cold+water%22+OR+%22hot+water%22+OR+%22water+canister%22+OR+%22water+tight%22+OR+%22+water+down%22+OR+%22flood+of+refugees%22+OR+Rivera+OR+Suez+OR+Panama+OR+oil+OR+drugs+OR+%22three+gorges%22+OR+waterski+OR+watermelon+OR+dishwater+OR+waterproof+OR+%E2%80%9Cwater+resistant%E2%80%9D+OR+%E2%80%9Cwater+bath%E2%80%9D+)&pdsearchtype=SearchBox&pdtypeofsearch=searchboxclick&pdsf=&pdquerytemplateid=&pdtimeline=undefined%7Calldates&pdfromadvancedsearchpage=true&ecomp=wxLg9kk&earg=pdpsf&prid=5923a166-d96f-4896-be04-8b410ab9a20e
A8: AMZN | B8: Amazon | C8: Molly | D8: N | E8: Update Sheet to 15 March 2024 | F8: In Progress | I8: search button will not work
A9: ANAK | B9: An Nahr Al Kabir | C9: Raunaq | D9: Y (1 July 2023) | E9: 1 July 2023 - 15 March 2024 | F9: Y | G9: ANAK_excel.xlsx | H9: Y | I9: https://advance-lexis-com.ezproxy.library.tufts.edu/search/?pdmfid=1516831&crid=cc93a4c4-5e84-47b0-b381-745024f8ec7e&pdpsf=&pdpost=&pdstartin=urn%3Ahlct%3A16&pdsearchterms=hlead(*water*+OR+river*+OR+lake+OR+dam+OR+stream+OR+tributary+OR+diversion+OR+irrigation+OR+pollution+OR+water+quality+OR+flood!+OR+drought!+OR+channel+OR+canal+OR+hydroelect!+OR+reservoir+OR+groundwater+OR+aquifer+OR+drought+OR+recharge+OR+%22water+table%22+OR+%22bore+hole%22)+and+hlead(treaty+OR+agree!+OR+negotiat!+OR+resolution+OR+commission+OR+secretariat+OR+joint+management+OR+basin+management+OR+peace+OR+accord+OR+%22peace+accord%22+OR+settle!+OR+cooperat!+OR+collaborat!+OR+disput!+OR+conflict!+OR+disagree!+OR+sanction!+OR+war+OR+troops+OR+%22letter+of+protest%22+OR+hostility+OR+%22shots+fired%22+OR+boycott+OR+protest!+OR+appeal+OR+intent+OR+reject+OR+threat!+OR+force+OR+coerce+OR+assault+OR+fight+OR+demand+OR+disapprove+OR+diploma!+OR+statement+OR+memorandum)+and+hlead(An+Nahr+Al+Kabir+OR+Nahr+Ibrahim)+and+not+hlead(ocean+OR+navigat!+OR+nuclear+OR+%22water+cannon%22+OR+%22light+water+reactor%22+OR+%22mineral+water%22+OR+%22hold+water%22+OR+%22cold+water%22+OR+%22hot+water%22+OR+%22water+canister%22+OR+%22water+tight%22+OR+%22+water+down%22+OR+%22flood+of+refugees%22+OR+Rivera+OR+Suez+OR+Panama+OR+oil+OR+drugs+OR+%22three+gorges%22+OR+waterski+OR+watermelon+OR+dishwater+OR+waterproof+OR+%22water+resistant%22+OR+%22water+bath%22+)&pdsearchtype=SearchBox&pdtypeofsearch=searchboxclick&pdsf=&pdquerytemplateid=&pdtimeline=undefined%7Calldates&pdfromadvancedsearchpage=true&ecomp=xxLg9kk&earg=pdpsf&prid=3e153b8f-e851-4639-9031-01a881cfdb32
A10: ANGE | B10: Angerman | C10: Raunaq | D10: Y (1 July 2023) | E10: 1 July 2023 - 15 March 2024 | F10: Y | G10: ANGE_excel.xlsx | H10: Y | I10: https://advance-lexis-com.ezproxy.library.tufts.edu/search/?pdmfid=1516831&crid=5cc87410-4e22-46a3-834d-e1dd20f5ca4a&pdpsf=&pdpost=&pdstartin=urn%3Ahlct%3A16&pdsearchterms=hlead(*water*+OR+river*+OR+lake+OR+dam+OR+stream+OR+tributary+OR+diversion+OR+irrigation+OR+pollution+OR+water+quality+OR+flood!+OR+drought!+OR+channel+OR+canal+OR+hydroelect!+OR+reservoir+OR+groundwater+OR+aquifer+OR+drought+OR+recharge+OR+%22water+table%22+OR+%22bore+hole%22)+and+hlead(treaty+OR+agree!+OR+negotiat!+OR+resolution+OR+commission+OR+secretariat+OR+joint+management+OR+basin+management+OR+peace+OR+accord+OR+%22peace+accord%22+OR+settle!+OR+cooperat!+OR+collaborat!+OR+disput!+OR+conflict!+OR+disagree!+OR+sanction!+OR+war+OR+troops+OR+%22letter+of+protest%22+OR+hostility+OR+%22shots+fired%22+OR+boycott+OR+protest!+OR+appeal+OR+intent+OR+reject+OR+threat!+OR+force+OR+coerce+OR+assault+OR+fight+OR+demand+OR+disapprove+OR+diploma!+OR+statement+OR+memorandum)+and+hlead(Angerman)+and+not+hlead(ocean+OR+navigat!+OR+nuclear+OR+%22water+cannon%22+OR+%22light+water+reactor%22+OR+%22mineral+water%22+OR+%22hold+water%22+OR+%22cold+water%22+OR+%22hot+water%22+OR+%22water+canister%22+OR+%22water+tight%22+OR+%22+water+down%22+OR+%22flood+of+refugees%22+OR+Rivera+OR+Suez+OR+Panama+OR+oil+OR+drugs+OR+%22three+gorges%22+OR+waterski+OR+watermelon+OR+dishwater+OR+waterproof+OR+%22water+resistant%22+OR+%22water+bath%22+)&pdsearchtype=SearchBox&pdtypeofsearch=searchboxclick&pdsf=&pdquerytemplateid=&pdtimeline=undefined%7Calldates&pdfromadvancedsearchpage=true&ecomp=xxLg9kk&earg=pdpsf&prid=11f9a7c2-3787-4e1f-abf0-aa84db7ef7dc
A11: ANNL | B11: Annole | C11: Rachel | D11: Y (1 July 2023) | E11: 1 July 2023 - 15 March 2024 | F11: Need Add to 2024 | G11: N/A
A12: ARAL | B12: Aral Sea | C12: Molly | D12: Y (1 July 2023) | E12: 1 July 2023 - 15 March 2024 | F12: Y | G12: ARAL_excel.xlsx | H12: Y | I12: https://advance-lexis-com.ezproxy.library.tufts.edu/search/?pdmfid=1516831&crid=5123f8a8-66d5-412b-9e68-8108147f3012&pdpsf=&pdpost=&pdstartin=urn%3Ahlct%3A16&pdsearchterms=hlead(*water*+OR+river*+OR+lake+OR+dam+OR+stream+OR+tributary+OR+diversion+OR+irrigation+OR+pollution+OR+water+quality+OR+flood!+OR+drought!+OR+channel+OR+canal+OR+hydroelect!+OR+reservoir+OR+groundwater+OR+aquifer+OR+drought+OR+recharge+OR+%22water+table%22+OR+%22bore+hole%22)+and+hlead(treaty+OR+agree!+OR+negotiat!+OR+resolution+OR+commission+OR+secretariat+OR+joint+management+OR+basin+management+OR+peace+OR+accord+OR+%22peace+accord%22+OR+settle!+OR+cooperat!+OR+collaborat!+OR+disput!+OR+conflict!+OR+disagree!+OR+sanction!+OR+war+OR+troops+OR+%22letter+of+protest%22+OR+hostility+OR+%22shots+fired%22+OR+boycott+OR+protest!+OR+appeal+OR+intent+OR+reject+OR+threat!+OR+force+OR+coerce+OR+assault+OR+fight+OR+demand+OR+disapprove+OR+diploma!+OR+statement+OR+memorandum)+and+hlead(Aral+OR+Syr+Daria+OR+Naryn+OR+Amu+Daria+OR+Syr+Darya+OR+Amu+Darya+OR+Akhangaran+OR+Chirchik)+and+not+hlead(ocean+OR+navigat!+OR+nuclear+OR+%22water+cannon%22+OR+%22light+water+reactor%22+OR+%22mineral+water%22+OR+%22hold+water%22+OR+%22cold+water%22+OR+%22hot+water%22+OR+%22water+canister%22+OR+%22water+tight%22+OR+%22+water+down%22+OR+%22flood+of+refugees%22+OR+Rivera+OR+Suez+OR+Panama+OR+oil+OR+drugs+OR+%22three+gorges%22+OR+waterski+OR+watermelon+OR+dishwater+OR+waterproof+OR+%22water+resistant%22+OR+%22water+bath%22+)&pdsearchtype=SearchBox&pdtypeofsearch=searchboxclick&pdsf=&pdquerytemplateid=&pdtimeline=undefined%7Calldates&pdfromadvancedsearchpage=true&ecomp=xxLg9kk&earg=pdpsf&prid=23f3da92-673e-45a2-9b9e-22ed73f58158
A13: ASIX | B13: Asi/Orontes | C13: Molly | D13: Y (1 July 2023) | E13: 1 July 2023 - 15 March 2024 | F13: Y | G13: ASIX_excel.xlsx | H13: Y | I13: https://advance-lexis-com.ezproxy.library.tufts.edu/search/?pdmfid=1516831&crid=125e1e8b-67f5-41c6-9bc4-892d7f24c175&pdpsf=&pdpost=&pdstartin=urn%3Ahlct%3A16&pdsearchterms=hlead(*water*+OR+river*+OR+lake+OR+dam+OR+stream+OR+tributary+OR+diversion+OR+irrigation+OR+pollution+OR+water+quality+OR+flood!+OR+drought!+OR+channel+OR+canal+OR+hydroelect!+OR+reservoir+OR+groundwater+OR+aquifer+OR+drought+OR+recharge+OR+%22water+table%22+OR+%22bore+hole%22)+and+hlead(treaty+OR+agree!+OR+negotiat!+OR+resolution+OR+commission+OR+secretariat+OR+joint+management+OR+basin+management+OR+peace+OR+accord+OR+%22peace+accord%22+OR+settle!+OR+cooperat!+OR+collaborat!+OR+disput!+OR+conflict!+OR+disagree!+OR+sanction!+OR+war+OR+troops+OR+%22letter+of+protest%22+OR+hostility+OR+%22shots+fired%22+OR+boycott+OR+protest!+OR+appeal+OR+intent+OR+reject+OR+threat!+OR+force+OR+coerce+OR+assault+OR+fight+OR+demand+OR+disapprove+OR+diploma!+OR+statement+OR+memorandum)+and+hlead(Asi+OR+Orontes+OR+Amik+Golu)+and+not+hlead(ocean+OR+navigat!+OR+nuclear+OR+%22water+cannon%22+OR+%22light+water+reactor%22+OR+%22mineral+water%22+OR+%22hold+water%22+OR+%22cold+water%22+OR+%22hot+water%22+OR+%22water+canister%22+OR+%22water+tight%22+OR+%22+water+down%22+OR+%22flood+of+refugees%22+OR+Rivera+OR+Suez+OR+Panama+OR+oil+OR+drugs+OR+%22three+gorges%22+OR+waterski+OR+watermelon+OR+dishwater+OR+waterproof+OR+%22water+resistant%22+OR+%22water+bath%22+)&pdsearchtype=SearchBox&pdtypeofsearch=searchboxclick&pdsf=&pdquerytemplateid=&pdtimeline=undefined%7Calldates&pdfromadvancedsearchpage=true&ecomp=xxLg9kk&earg=pdpsf&prid=23f3da92-673e-45a2-9b9e-22ed73f58158
A14: ATBN | B14: Artibonite | C14: Raunaq | D14: Y (1 July 2023) | E14: 1 July 2023 - 15 March 2024 | F14: Y | G14: ATBN_excel.xlsx | H14: Y | I14: https://advance-lexis-com.ezproxy.library.tufts.edu/search/?pdmfid=1516831&crid=1c630e8f-6daf-4129-b0df-b86e28979d77&pdpsf=&pdpost=&pdstartin=urn%3Ahlct%3A16&pdsearchterms=hlead(*water*+OR+river*+OR+lake+OR+dam+OR+stream+OR+tributary+OR+diversion+OR+irrigation+OR+pollution+OR+water+quality+OR+flood!+OR+drought!+OR+channel+OR+canal+OR+hydroelect!+OR+reservoir+OR+groundwater+OR+aquifer+OR+drought+OR+recharge+OR+%22water+table%22+OR+%22bore+hole%22)+and+hlead(treaty+OR+agree!+OR+negotiat!+OR+resolution+OR+commission+OR+secretariat+OR+joint+management+OR+basin+management+OR+peace+OR+accord+OR+%22peace+accord%22+OR+settle!+OR+cooperat!+OR+collaborat!+OR+disput!+OR+conflict!+OR+disagree!+OR+sanction!+OR+war+OR+troops+OR+%22letter+of+protest%22+OR+hostility+OR+%22shots+fired%22+OR+boycott+OR+protest!+OR+appeal+OR+intent+OR+reject+OR+threat!+OR+force+OR+coerce+OR+assault+OR+fight+OR+demand+OR+disapprove+OR+diploma!+OR+statement+OR+memorandum)+and+hlead(Artibonite+OR+Depeligre)+and+not+hlead(ocean+OR+navigat!+OR+nuclear+OR+%22water+cannon%22+OR+%22light+water+reactor%22+OR+%22mineral+water%22+OR+%22hold+water%22+OR+%22cold+water%22+OR+%22hot+water%22+OR+%22water+canister%22+OR+%22water+tight%22+OR+%22+water+down%22+OR+%22flood+of+refugees%22+OR+Rivera+OR+Suez+OR+Panama+OR+oil+OR+drugs+OR+%22three+gorges%22+OR+waterski+OR+watermelon+OR+dishwater+OR+waterproof+OR+%22water+resistant%22+OR+%22water+bath%22+)&pdsearchtype=SearchBox&pdtypeofsearch=searchboxclick&pdsf=&pdquerytemplateid=&pdtimeline=undefined%7Calldates&pdfromadvancedsearchpage=true&ecomp=xxLg9kk&earg=pdpsf&prid=23f3da92-673e-45a2-9b9e-22ed73f58158
A15: ATCY | B15: Astara Chay | C15: Raunaq | D15: Y (1 July 2023) | E15: 1 July 2023 - 15 March 2024 | G15: No results | I15: https://advance-lexis-com.ezproxy.library.tufts.edu/search/?pdmfid=1516831&crid=9908ff38-8b27-4fe7-b8b0-a20e85ff405c&pdpsf=&pdpost=&pdstartin=urn%3Ahlct%3A16&pdsearchterms=hlead(*water*+OR+river*+OR+lake+OR+dam+OR+stream+OR+tributary+OR+diversion+OR+irrigation+OR+pollution+OR+water+quality+OR+flood!+OR+drought!+OR+channel+OR+canal+OR+hydroelect!+OR+reservoir+OR+groundwater+OR+aquifer+OR+drought+OR+recharge+OR+%22water+table%22+OR+%22bore+hole%22)+and+hlead(treaty+OR+agree!+OR+negotiat!+OR+resolution+OR+commission+OR+secretariat+OR+joint+management+OR+basin+management+OR+peace+OR+accord+OR+%22peace+accord%22+OR+settle!+OR+cooperat!+OR+collaborat!+OR+disput!+OR+conflict!+OR+disagree!+OR+sanction!+OR+war+OR+troops+OR+%22letter+of+protest%22+OR+hostility+OR+%22shots+fired%22+OR+boycott+OR+protest!+OR+appeal+OR+intent+OR+reject+OR+threat!+OR+force+OR+coerce+OR+assault+OR+fight+OR+demand+OR+disapprove+OR+diploma!+OR+statement+OR+memorandum)+and+hlead(Astara+Chay)+and+not+hlead(ocean+OR+navigat!+OR+nuclear+OR+%22water+cannon%22+OR+%22light+water+reactor%22+OR+%22mineral+water%22+OR+%22hold+water%22+OR+%22cold+water%22+OR+%22hot+water%22+OR+%22water+canister%22+OR+%22water+tight%22+OR+%22+water+down%22+OR+%22flood+of+refugees%22+OR+Rivera+OR+Suez+OR+Panama+OR+oil+OR+drugs+OR+%22three+gorges%22+OR+waterski+OR+watermelon+OR+dishwater+OR+waterproof+OR+%22water+resistant%22+OR+%22water+bath%22+)&pdsearchtype=SearchBox&pdtypeofsearch=searchboxclick&pdsf=&pdquerytemplateid=&pdtimeline=undefined%7Calldates&pdfromadvancedsearchpage=true&ecomp=xxLg9kk&earg=pdpsf&prid=23f3da92-673e-45a2-9b9e-22ed73f58158
A16: ATRK | B16: Atrak | C16: Raunaq | D16: Y (1 July 2023) | E16: 1 July 2023 - 15 March 2024 | F16: Y | G16: ATRK_excel.xlsx | H16: Y | I16: https://advance-lexis-com.ezproxy.library.tufts.edu/search/?pdmfid=1516831&crid=d7c8c0bd-2a77-4637-87c0-4bda5500c8a4&pdpsf=&pdpost=&pdstartin=urn%3Ahlct%3A16&pdsearchterms=hlead(*water*+OR+river*+OR+lake+OR+dam+OR+stream+OR+tributary+OR+diversion+OR+irrigation+OR+pollution+OR+water+quality+OR+flood!+OR+drought!+OR+channel+OR+canal+OR+hydroelect!+OR+reservoir+OR+groundwater+OR+aquifer+OR+drought+OR+recharge+OR+%22water+table%22+OR+%22bore+hole%22)+and+hlead(treaty+OR+agree!+OR+negotiat!+OR+resolution+OR+commission+OR+secretariat+OR+joint+management+OR+basin+management+OR+peace+OR+accord+OR+%22peace+accord%22+OR+settle!+OR+cooperat!+OR+collaborat!+OR+disput!+OR+conflict!+OR+disagree!+OR+sanction!+OR+war+OR+troops+OR+%22letter+of+protest%22+OR+hostility+OR+%22shots+fired%22+OR+boycott+OR+protest!+OR+appeal+OR+intent+OR+reject+OR+threat!+OR+force+OR+coerce+OR+assault+OR+fight+OR+demand+OR+disapprove+OR+diploma!+OR+statement+OR+memorandum)+and+hlead(Atrak+OR+Sumber)+and+not+hlead(ocean+OR+navigat!+OR+nuclear+OR+%22water+cannon%22+OR+%22light+water+reactor%22+OR+%22mineral+water%22+OR+%22hold+water%22+OR+%22cold+water%22+OR+%22hot+water%22+OR+%22water+canister%22+OR+%22water+tight%22+OR+%22+water+down%22+OR+%22flood+of+refugees%22+OR+Rivera+OR+Suez+OR+Panama+OR+oil+OR+drugs+OR+%22three+gorges%22+OR+waterski+OR+watermelon+OR+dishwater+OR+waterproof+OR+%22water+resistant%22+OR+%22water+bath%22+)&pdsearchtype=SearchBox&pdtypeofsearch=searchboxclick&pdsf=&pdquerytemplateid=&pdtimeline=undefined%7Calldates&pdfromadvancedsearchpage=true&ecomp=xxLg9kk&earg=pdpsf&prid=23f3da92-673e-45a2-9b9e-22ed73f58158
A17: AVLS | B17: Aviles | C17: Raunaq | D17: Y (1 July 2023) | E17: 1 July 2023 - 15 March 2024 | F17: Y | G17: AVLS_excel.xlsx | H17: Y | I17: https://advance-lexis-com.ezproxy.library.tufts.edu/search/?pdmfid=1516831&crid=8c2a0306-6bd5-43e9-9f2f-e43f16156521&pdpsf=&pdpost=&pdstartin=urn%3Ahlct%3A16&pdsearchterms=hlead(*water*+OR+river*+OR+lake+OR+dam+OR+stream+OR+tributary+OR+diversion+OR+irrigation+OR+pollution+OR+water+quality+OR+flood!+OR+drought!+OR+channel+OR+canal+OR+hydroelect!+OR+reservoir+OR+groundwater+OR+aquifer+OR+drought+OR+recharge+OR+%22water+table%22+OR+%22bore+hole%22)+and+hlead(treaty+OR+agree!+OR+negotiat!+OR+resolution+OR+commission+OR+secretariat+OR+joint+management+OR+basin+management+OR+peace+OR+accord+OR+%22peace+accord%22+OR+settle!+OR+cooperat!+OR+collaborat!+OR+disput!+OR+conflict!+OR+disagree!+OR+sanction!+OR+war+OR+troops+OR+%22letter+of+protest%22+OR+hostility+OR+%22shots+fired%22+OR+boycott+OR+protest!+OR+appeal+OR+intent+OR+reject+OR+threat!+OR+force+OR+coerce+OR+assault+OR+fight+OR+demand+OR+disapprove+OR+diploma!+OR+statement+OR+memorandum)+and+hlead(Aviles)+and+not+hlead(ocean+OR+navigat!+OR+nuclear+OR+%22water+cannon%22+OR+%22light+water+reactor%22+OR+%22mineral+water%22+OR+%22hold+water%22+OR+%22cold+water%22+OR+%22hot+water%22+OR+%22water+canister%22+OR+%22water+tight%22+OR+%22+water+down%22+OR+%22flood+of+refugees%22+OR+Rivera+OR+Suez+OR+Panama+OR+oil+OR+drugs+OR+%22three+gorges%22+OR+waterski+OR+watermelon+OR+dishwater+OR+waterproof+OR+%22water+resistant%22+OR+%22water+bath%22+)&pdsearchtype=SearchBox&pdtypeofsearch=searchboxclick&pdsf=&pdquerytemplateid=&pdtimeline=undefined%7Calldates&pdfromadvancedsearchpage=true&ecomp=xxLg9kk&earg=pdpsf&prid=23f3da92-673e-45a2-9b9e-22ed73f58158
A18: AWSH | B18: Awash | C18: Molly | D18: Y (1 July 2023) | E18: 1 July 2023 - 15 March 2024 | F18: Y | G18: AWSH_excel.xlsx | H18: Y | I18: https://advance-lexis-com.ezproxy.library.tufts.edu/search/?pdmfid=1516831&crid=13500b23-77c4-4282-8bd0-7f0e38d4fe6a&pdpsf=&pdpost=&pdstartin=urn%3Ahlct%3A16&pdsearchterms=hlead(*water*+OR+river*+OR+lake+OR+dam+OR+stream+OR+tributary+OR+diversion+OR+irrigation+OR+pollution+OR+water+quality+OR+flood!+OR+drought!+OR+channel+OR+canal+OR+hydroelect!+OR+reservoir+OR+groundwater+OR+aquifer+OR+drought+OR+recharge+OR+%22water+table%22+OR+%22bore+hole%22)+and+hlead(treaty+OR+agree!+OR+negotiat!+OR+resolution+OR+commission+OR+secretariat+OR+joint+management+OR+basin+management+OR+peace+OR+accord+OR+%22peace+accord%22+OR+settle!+OR+cooperat!+OR+collaborat!+OR+disput!+OR+conflict!+OR+disagree!+OR+sanction!+OR+war+OR+troops+OR+%22letter+of+protest%22+OR+hostility+OR+%22shots+fired%22+OR+boycott+OR+protest!+OR+appeal+OR+intent+OR+reject+OR+threat!+OR+force+OR+coerce+OR+assault+OR+fight+OR+demand+OR+disapprove+OR+diploma!+OR+statement+OR+memorandum)+and+hlead(Abhe+Bid+Hayak+OR+Awash+OR+Finochaa+OR+Gemeri+Hayak+OR+Petit+Akabi+OR+Sendafa)+and+not+hlead(ocean+OR+navigat!+OR+nuclear+OR+%22water+cannon%22+OR+%22light+water+reactor%22+OR+%22mineral+water%22+OR+%22hold+water%22+OR+%22cold+water%22+OR+%22hot+water%22+OR+%22water+canister%22+OR+%22water+tight%22+OR+%22+water+down%22+OR+%22flood+of+refugees%22+OR+Rivera+OR+Suez+OR+Panama+OR+oil+OR+drugs+OR+%22three+gorges%22+OR+waterski+OR+watermelon+OR+dishwater+OR+waterproof+OR+%22water+resistant%22+OR+%22water+bath%22+)&pdsearchtype=SearchBox&pdtypeofsearch=searchboxclick&pdsf=&pdquerytemplateid=&pdtimeline=undefined%7Calldates&pdfromadvancedsearchpage=true&ecomp=xxLg9kk&earg=pdpsf&prid=23f3da92-673e-45a2-9b9e-22ed73f58158
A19: AYSN | B19: Aysen | C19: Raunaq | D19: Y (1 July 2023) | E19: 1 July 2023 - 15 March 2024 | F19: Y | G19: AYSN_excel.xlsx | H19: Y | I19: https://advance-lexis-com.ezproxy.library.tufts.edu/search/?pdmfid=1516831&crid=d8fcd9d3-f35d-406d-9efc-b83edc6b50ef&pdpsf=&pdpost=&pdstartin=urn%3Ahlct%3A16&pdsearchterms=hlead(*water*+OR+river*+OR+lake+OR+dam+OR+stream+OR+tributary+OR+diversion+OR+irrigation+OR+pollution+OR+water+quality+OR+flood!+OR+drought!+OR+channel+OR+canal+OR+hydroelect!+OR+reservoir+OR+groundwater+OR+aquifer+OR+drought+OR+recharge+OR+%22water+table%22+OR+%22bore+hole%22)+and+hlead(treaty+OR+agree!+OR+negotiat!+OR+resolution+OR+commission+OR+secretariat+OR+joint+management+OR+basin+management+OR+peace+OR+accord+OR+%22peace+accord%22+OR+settle!+OR+cooperat!+OR+collaborat!+OR+disput!+OR+conflict!+OR+disagree!+OR+sanction!+OR+war+OR+troops+OR+%22letter+of+protest%22+OR+hostility+OR+%22shots+fired%22+OR+boycott+OR+protest!+OR+appeal+OR+intent+OR+reject+OR+threat!+OR+force+OR+coerce+OR+assault+OR+fight+OR+demand+OR+disapprove+OR+diploma!+OR+statement+OR+memorandum)+and+hlead(Aysen)+and+not+hlead(ocean+OR+navigat!+OR+nuclear+OR+%22water+cannon%22+OR+%22light+water+reactor%22+OR+%22mineral+water%22+OR+%22hold+water%22+OR+%22cold+water%22+OR+%22hot+water%22+OR+%22water+canister%22+OR+%22water+tight%22+OR+%22+water+down%22+OR+%22flood+of+refugees%22+OR+Rivera+OR+Suez+OR+Panama+OR+oil+OR+drugs+OR+%22three+gorges%22+OR+waterski+OR+watermelon+OR+dishwater+OR+waterproof+OR+%22water+resistant%22+OR+%22water+bath%22+)&pdsearchtype=SearchBox&pdtypeofsearch=searchboxclick&pdsf=&pdquerytemplateid=&pdtimeline=undefined%7Calldates&pdfromadvancedsearchpage=true&ecomp=xxLg9kk&earg=pdpsf&prid=23f3da92-673e-45a2-9b9e-22ed73f58158
A20: BAKR | B20: Baker | C20: Selena | D20: N | E20: Update Sheet to 15 March 2024 | F20: Y | G20: BAKR_excel.xlsx | H20: Y | I20: https://advance-lexis-com.ezproxy.library.tufts.edu/search/?pdmfid=1516831&crid=2765f148-e3e7-4702-8620-72fa608c3e66&pdpsf=&pdpost=&pdstartin=urn%3Ahlct%3A16&pdsearchterms=hlead(*water*+OR+river*+OR+lake+OR+dam+OR+stream+OR+tributary+OR+diversion+OR+irrigation+OR+pollution+OR+water+quality+OR+flood!+OR+drought!+OR+channel+OR+canal+OR+hydroelect!+OR+reservoir+OR+groundwater+OR+aquifer+OR+drought+OR+recharge+OR+%22water+table%22+OR+%22bore+hole%22)+and+hlead(treaty+OR+agree!+OR+negotiat!+OR+resolution+OR+commission+OR+secretariat+OR+joint+management+OR+basin+management+OR+peace+OR+accord+OR+%22peace+accord%22+OR+settle!+OR+cooperat!+OR+collaborat!+OR+disput!+OR+conflict!+OR+disagree!+OR+sanction!+OR+war+OR+troops+OR+%22letter+of+protest%22+OR+hostility+OR+%22shots+fired%22+OR+boycott+OR+protest!+OR+appeal+OR+intent+OR+reject+OR+threat!+OR+force+OR+coerce+OR+assault+OR+fight+OR+demand+OR+disapprove+OR+diploma!+OR+statement+OR+memorandum)+and+hlead(Baker+OR+Cochrane)+and+not+hlead(ocean+OR+navigat!+OR+nuclear+OR+%22water+cannon%22+OR+%22light+water+reactor%22+OR+%22mineral+water%22+OR+%22hold+water%22+OR+%22cold+water%22+OR+%22hot+water%22+OR+%22water+canister%22+OR+%22water+tight%22+OR+%22+water+down%22+OR+%22flood+of+refugees%22+OR+Rivera+OR+Suez+OR+Panama+OR+oil+OR+drugs+OR+%22three+gorges%22+OR+waterski+OR+watermelon+OR+dishwater+OR+waterproof+OR+%E2%80%9Cwater+resistant%E2%80%9D+OR+%E2%80%9Cwater+bath%E2%80%9D+)&pdsearchtype=SearchBox&pdtypeofsearch=searchboxclick&pdsf=&pdquerytemplateid=&pdtimeline=undefined%7Calldates&pdfromadvancedsearchpage=true&ecomp=wxLg9kk&earg=pdpsf&prid=5923a166-d96f-4896-be04-8b410ab9a20e
A21: BANN | B21: Bann | C21: Molly | D21: Y (1 July 2023) | E21: 1 July 2023 - 15 March 2024 | F21: Y | G21: BANN_excel.xlsx | H21: Y | I21: https://advance-lexis-com.ezproxy.library.tufts.edu/search/?pdmfid=1516831&crid=bdf289b9-2548-42b2-a0c9-f8d1687acb8d&pdpsf=&pdpost=&pdstartin=urn%3Ahlct%3A16&pdsearchterms=hlead(*water*+OR+river*+OR+lake+OR+dam+OR+stream+OR+tributary+OR+diversion+OR+irrigation+OR+pollution+OR+water+quality+OR+flood!+OR+drought!+OR+channel+OR+canal+OR+hydroelect!+OR+reservoir+OR+groundwater+OR+aquifer+OR+drought+OR+recharge+OR+%22water+table%22+OR+%22bore+hole%22)+and+hlead(treaty+OR+agree!+OR+negotiat!+OR+resolution+OR+commission+OR+secretariat+OR+joint+management+OR+basin+management+OR+peace+OR+accord+OR+%22peace+accord%22+OR+settle!+OR+cooperat!+OR+collaborat!+OR+disput!+OR+conflict!+OR+disagree!+OR+sanction!+OR+war+OR+troops+OR+%22letter+of+protest%22+OR+hostility+OR+%22shots+fired%22+OR+boycott+OR+protest!+OR+appeal+OR+intent+OR+reject+OR+threat!+OR+force+OR+coerce+OR+assault+OR+fight+OR+demand+OR+disapprove+OR+diploma!+OR+statement+OR+memorandum)+and+hlead(Bann+OR+CAPS(Black+Water)+OR+Laugh+Neagh+OR+CAPS(Lower+Laugh)+Erine)+and+not+hlead(ocean+OR+navigat!+OR+nuclear+OR+%22water+cannon%22+OR+%22light+water+reactor%22+OR+%22mineral+water%22+OR+%22hold+water%22+OR+%22cold+water%22+OR+%22hot+water%22+OR+%22water+canister%22+OR+%22water+tight%22+OR+%22+water+down%22+OR+%22flood+of+refugees%22+OR+Rivera+OR+Suez+OR+Panama+OR+oil+OR+drugs+OR+%22three+gorges%22+OR+waterski+OR+watermelon+OR+dishwater+OR+waterproof+OR+%22water+resistant%22+OR+%22water+bath%22+)&pdsearchtype=SearchBox&pdtypeofsearch=searchboxclick&pdsf=&pdquerytemplateid=&pdtimeline=undefined%7Calldates&pdfromadvancedsearchpage=true&ecomp=xxLg9kk&earg=pdpsf&prid=23f3da92-673e-45a2-9b9e-22ed73f58158
A22: BATU | B22: Bahr at Tubat | C22: Raunaq | D22: Y (1 July 2023) | E22: 1 July 2023 - 15 March 2024 | G22: No results | I22: https://advance-lexis-com.ezproxy.library.tufts.edu/search/?pdmfid=1516831&crid=05dd58a7-7328-4bd8-be6c-fab6fa677d83&pdpsf=&pdpost=&pdstartin=urn%3Ahlct%3A16&pdsearchterms=hlead(*water*+OR+river*+OR+lake+OR+dam+OR+stream+OR+tributary+OR+diversion+OR+irrigation+OR+pollution+OR+water+quality+OR+flood!+OR+drought!+OR+channel+OR+canal+OR+hydroelect!+OR+reservoir+OR+groundwater+OR+aquifer+OR+drought+OR+recharge+OR+%22water+table%22+OR+%22bore+hole%22)+and+hlead(treaty+OR+agree!+OR+negotiat!+OR+resolution+OR+commission+OR+secretariat+OR+joint+management+OR+basin+management+OR+peace+OR+accord+OR+%22peace+accord%22+OR+settle!+OR+cooperat!+OR+collaborat!+OR+disput!+OR+conflict!+OR+disagree!+OR+sanction!+OR+war+OR+troops+OR+%22letter+of+protest%22+OR+hostility+OR+%22shots+fired%22+OR+boycott+OR+protest!+OR+appeal+OR+intent+OR+reject+OR+threat!+OR+force+OR+coerce+OR+assault+OR+fight+OR+demand+OR+disapprove+OR+diploma!+OR+statement+OR+memorandum)+and+hlead(Bahr+at+Tubat)+and+not+hlead(ocean+OR+navigat!+OR+nuclear+OR+%22water+cannon%22+OR+%22light+water+reactor%22+OR+%22mineral+water%22+OR+%22hold+water%22+OR+%22cold+water%22+OR+%22hot+water%22+OR+%22water+canister%22+OR+%22water+tight%22+OR+%22+water+down%22+OR+%22flood+of+refugees%22+OR+Rivera+OR+Suez+OR+Panama+OR+oil+OR+drugs+OR+%22three+gorges%22+OR+waterski+OR+watermelon+OR+dishwater+OR+waterproof+OR+%22water+resistant%22+OR+%22water+bath%22+)&pdsearchtype=SearchBox&pdtypeofsearch=searchboxclick&pdsf=&pdquerytemplateid=&pdtimeline=undefined%7Calldates&pdfromadvancedsearchpage=true&ecomp=xxLg9kk&earg=pdpsf&prid=23f3da92-673e-45a2-9b9e-22ed73f58158
A23: BDSO | B23: Bidasoa | C23: Raunaq | D23: Y (1 July 2023) | E23: 1 July 2023 - 15 March 2024 | F23: Y | G23: BDSO_excel.xlsx | H23: Y | I23: https://advance-lexis-com.ezproxy.library.tufts.edu/search/?pdmfid=1516831&crid=f5c75d3c-cf7a-4550-ba19-5bd871ca8a5a&pdpsf=&pdpost=&pdstartin=urn%3Ahlct%3A16&pdsearchterms=hlead(*water*+OR+river*+OR+lake+OR+dam+OR+stream+OR+tributary+OR+diversion+OR+irrigation+OR+pollution+OR+water+quality+OR+flood!+OR+drought!+OR+channel+OR+canal+OR+hydroelect!+OR+reservoir+OR+groundwater+OR+aquifer+OR+drought+OR+recharge+OR+%22water+table%22+OR+%22bore+hole%22)+and+hlead(treaty+OR+agree!+OR+negotiat!+OR+resolution+OR+commission+OR+secretariat+OR+joint+management+OR+basin+management+OR+peace+OR+accord+OR+%22peace+accord%22+OR+settle!+OR+cooperat!+OR+collaborat!+OR+disput!+OR+conflict!+OR+disagree!+OR+sanction!+OR+war+OR+troops+OR+%22letter+of+protest%22+OR+hostility+OR+%22shots+fired%22+OR+boycott+OR+protest!+OR+appeal+OR+intent+OR+reject+OR+threat!+OR+force+OR+coerce+OR+assault+OR+fight+OR+demand+OR+disapprove+OR+diploma!+OR+statement+OR+memorandum)+and+hlead(Bidasoa)+and+not+hlead(ocean+OR+navigat!+OR+nuclear+OR+%22water+cannon%22+OR+%22light+water+reactor%22+OR+%22mineral+water%22+OR+%22hold+water%22+OR+%22cold+water%22+OR+%22hot+water%22+OR+%22water+canister%22+OR+%22water+tight%22+OR+%22+water+down%22+OR+%22flood+of+refugees%22+OR+Rivera+OR+Suez+OR+Panama+OR+oil+OR+drugs+OR+%22three+gorges%22+OR+waterski+OR+watermelon+OR+dishwater+OR+waterproof+OR+%22water+resistant%22+OR+%22water+bath%22+)&pdsearchtype=SearchBox&pdtypeofsearch=searchboxclick&pdsf=&pdquerytemplateid=&pdtimeline=undefined%7Calldates&pdfromadvancedsearchpage=true&ecomp=xxLg9kk&earg=pdpsf&prid=23f3da92-673e-45a2-9b9e-22ed73f58158
A24: BENT | B24: Benito/Ntem | C24: Raunaq | D24: N | E24: Update Sheet to 15 March 2024 | F24: Need Add to 2024 | G24: BENT_excel.xlsx | I24: https://advance-lexis-com.ezproxy.library.tufts.edu/search/?pdmfid=1516831&crid=9354e9ef-0eaa-4cf0-aa72-d327a5092ae5&pdpsf=&pdpost=&pdstartin=urn%3Ahlct%3A16&pdsearchterms=hlead(*water*+OR+river*+OR+lake+OR+dam+OR+stream+OR+tributary+OR+diversion+OR+irrigation+OR+pollution+OR+water+quality+OR+flood!+OR+drought!+OR+channel+OR+canal+OR+hydroelect!+OR+reservoir+OR+groundwater+OR+aquifer+OR+drought+OR+recharge+OR+%22water+table%22+OR+%22bore+hole%22)+and+hlead(treaty+OR+agree!+OR+negotiat!+OR+resolution+OR+commission+OR+secretariat+OR+joint+management+OR+basin+management+OR+peace+OR+accord+OR+%22peace+accord%22+OR+settle!+OR+cooperat!+OR+collaborat!+OR+disput!+OR+conflict!+OR+disagree!+OR+sanction!+OR+war+OR+troops+OR+%22letter+of+protest%22+OR+hostility+OR+%22shots+fired%22+OR+boycott+OR+protest!+OR+appeal+OR+intent+OR+reject+OR+threat!+OR+force+OR+coerce+OR+assault+OR+fight+OR+demand+OR+disapprove+OR+diploma!+OR+statement+OR+memorandum)+and+hlead(Benito+OR+Ntem)+and+not+hlead(ocean+OR+navigat!+OR+nuclear+OR+%22water+cannon%22+OR+%22light+water+reactor%22+OR+%22mineral+water%22+OR+%22hold+water%22+OR+%22cold+water%22+OR+%22hot+water%22+OR+%22water+canister%22+OR+%22water+tight%22+OR+%22+water+down%22+OR+%22flood+of+refugees%22+OR+Rivera+OR+Suez+OR+Panama+OR+oil+OR+drugs+OR+%22three+gorges%22+OR+waterski+OR+watermelon+OR+dishwater+OR+waterproof+OR+%E2%80%9Cwater+resistant%E2%80%9D+OR+%E2%80%9Cwater+bath%E2%80%9D+)&pdsearchtype=SearchBox&pdtypeofsearch=searchboxclick&pdsf=&pdquerytemplateid=&pdtimeline=06%2F30%2F2008to07%2F01%2F2023%7Cdatebetween&pdfromadvancedsearchpage=true&ecomp=qxLg9kk&earg=pdpsf&prid=fea21021-dc37-4a81-b832-05155671fa9c
A25: BIAX | B25: Bia | C25: Molly | D25: Y (1 July 2023) | E25: 1 July 2023 - 15 March 2024 | F25: Y | G25: BIAX_excel.xlsx | H25: Y | I25: https://advance-lexis-com.ezproxy.library.tufts.edu/search/?pdmfid=1516831&crid=92b2a1b4-db1b-411e-8c2e-920b95ed23da&pdpsf=&pdpost=&pdstartin=urn%3Ahlct%3A16&pdsearchterms=hlead(*water*+OR+river*+OR+lake+OR+dam+OR+stream+OR+tributary+OR+diversion+OR+irrigation+OR+pollution+OR+water+quality+OR+flood!+OR+drought!+OR+channel+OR+canal+OR+hydroelect!+OR+reservoir+OR+groundwater+OR+aquifer+OR+drought+OR+recharge+OR+%22water+table%22+OR+%22bore+hole%22)+and+hlead(treaty+OR+agree!+OR+negotiat!+OR+resolution+OR+commission+OR+secretariat+OR+joint+management+OR+basin+management+OR+peace+OR+accord+OR+%22peace+accord%22+OR+settle!+OR+cooperat!+OR+collaborat!+OR+disput!+OR+conflict!+OR+disagree!+OR+sanction!+OR+war+OR+troops+OR+%22letter+of+protest%22+OR+hostility+OR+%22shots+fired%22+OR+boycott+OR+protest!+OR+appeal+OR+intent+OR+reject+OR+threat!+OR+force+OR+coerce+OR+assault+OR+fight+OR+demand+OR+disapprove+OR+diploma!+OR+statement+OR+memorandum)+and+hlead(Bia)+and+not+hlead(ocean+OR+navigat!+OR+nuclear+OR+%22water+cannon%22+OR+%22light+water+reactor%22+OR+%22mineral+water%22+OR+%22hold+water%22+OR+%22cold+water%22+OR+%22hot+water%22+OR+%22water+canister%22+OR+%22water+tight%22+OR+%22+water+down%22+OR+%22flood+of+refugees%22+OR+Rivera+OR+Suez+OR+Panama+OR+oil+OR+drugs+OR+%22three+gorges%22+OR+waterski+OR+watermelon+OR+dishwater+OR+waterproof+OR+%22water+resistant%22+OR+%22water+bath%22+)&pdsearchtype=SearchBox&pdtypeofsearch=searchboxclick&pdsf=&pdquerytemplateid=&pdtimeline=undefined%7Calldates&pdfromadvancedsearchpage=true&ecomp=xxLg9kk&earg=pdpsf&prid=23f3da92-673e-45a2-9b9e-22ed73f58158
A26: BLUN | B26: Beilun | C26: Raunaq | D26: Y (1 July 2023) | E26: 1 July 2023 - 15 March 2024 | F26: Y | G26: BLUN_excel.xlsx | H26: Y | I26: https://advance-lexis-com.ezproxy.library.tufts.edu/search/?pdmfid=1516831&crid=e888d314-77f7-4e3f-a2f1-865073da9bbc&pdpsf=&pdpost=&pdstartin=urn%3Ahlct%3A16&pdsearchterms=hlead(*water*+OR+river*+OR+lake+OR+dam+OR+stream+OR+tributary+OR+diversion+OR+irrigation+OR+pollution+OR+water+quality+OR+flood!+OR+drought!+OR+channel+OR+canal+OR+hydroelect!+OR+reservoir+OR+groundwater+OR+aquifer+OR+drought+OR+recharge+OR+%22water+table%22+OR+%22bore+hole%22)+and+hlead(treaty+OR+agree!+OR+negotiat!+OR+resolution+OR+commission+OR+secretariat+OR+joint+management+OR+basin+management+OR+peace+OR+accord+OR+%22peace+accord%22+OR+settle!+OR+cooperat!+OR+collaborat!+OR+disput!+OR+conflict!+OR+disagree!+OR+sanction!+OR+war+OR+troops+OR+%22letter+of+protest%22+OR+hostility+OR+%22shots+fired%22+OR+boycott+OR+protest!+OR+appeal+OR+intent+OR+reject+OR+threat!+OR+force+OR+coerce+OR+assault+OR+fight+OR+demand+OR+disapprove+OR+diploma!+OR+statement+OR+memorandum)+and+hlead(Beilun)+and+not+hlead(ocean+OR+navigat!+OR+nuclear+OR+%22water+cannon%22+OR+%22light+water+reactor%22+OR+%22mineral+water%22+OR+%22hold+water%22+OR+%22cold+water%22+OR+%22hot+water%22+OR+%22water+canister%22+OR+%22water+tight%22+OR+%22+water+down%22+OR+%22flood+of+refugees%22+OR+Rivera+OR+Suez+OR+Panama+OR+oil+OR+drugs+OR+%22three+gorges%22+OR+waterski+OR+watermelon+OR+dishwater+OR+waterproof+OR+%22water+resistant%22+OR+%22water+bath%22+)&pdsearchtype=SearchBox&pdtypeofsearch=searchboxclick&pdsf=&pdquerytemplateid=&pdtimeline=undefined%7Calldates&pdfromadvancedsearchpage=true&ecomp=xxLg9kk&earg=pdpsf&prid=23f3da92-673e-45a2-9b9e-22ed73f58158
A27: BLZE | B27: Belize | C27: Molly | D27: Y (1 July 2023) | E27: 1 July 2023 - 15 March 2024 | F27: Y | G27: BLZE_excel.xlsx | H27: Y | I27: https://advance-lexis-com.ezproxy.library.tufts.edu/search/?pdmfid=1516831&crid=f7b4e445-5373-4006-aeb7-2496d0d52126&pdpsf=&pdpost=&pdstartin=urn%3Ahlct%3A16&pdsearchterms=hlead(*water*+OR+river*+OR+lake+OR+dam+OR+stream+OR+tributary+OR+diversion+OR+irrigation+OR+pollution+OR+water+quality+OR+flood!+OR+drought!+OR+channel+OR+canal+OR+hydroelect!+OR+reservoir+OR+groundwater+OR+aquifer+OR+drought+OR+recharge+OR+%22water+table%22+OR+%22bore+hole%22)+and+hlead(treaty+OR+agree!+OR+negotiat!+OR+resolution+OR+commission+OR+secretariat+OR+joint+management+OR+basin+management+OR+peace+OR+accord+OR+%22peace+accord%22+OR+settle!+OR+cooperat!+OR+collaborat!+OR+disput!+OR+conflict!+OR+disagree!+OR+sanction!+OR+war+OR+troops+OR+%22letter+of+protest%22+OR+hostility+OR+%22shots+fired%22+OR+boycott+OR+protest!+OR+appeal+OR+intent+OR+reject+OR+threat!+OR+force+OR+coerce+OR+assault+OR+fight+OR+demand+OR+disapprove+OR+diploma!+OR+statement+OR+memorandum)+and+hlead(Belize+OR+Mopan)+and+not+hlead(ocean+OR+navigat!+OR+nuclear+OR+%22water+cannon%22+OR+%22light+water+reactor%22+OR+%22mineral+water%22+OR+%22hold+water%22+OR+%22cold+water%22+OR+%22hot+water%22+OR+%22water+canister%22+OR+%22water+tight%22+OR+%22+water+down%22+OR+%22flood+of+refugees%22+OR+Rivera+OR+Suez+OR+Panama+OR+oil+OR+drugs+OR+%22three+gorges%22+OR+waterski+OR+watermelon+OR+dishwater+OR+waterproof+OR+%22water+resistant%22+OR+%22water+bath%22+)&pdsearchtype=SearchBox&pdtypeofsearch=searchboxclick&pdsf=&pdquerytemplateid=&pdtimeline=undefined%7Calldates&pdfromadvancedsearchpage=true&ecomp=xxLg9kk&earg=pdpsf&prid=23f3da92-673e-45a2-9b9e-22ed73f58158
A28: BNGU | B28: Bangau | C28: Raunaq | D28: Y (1 July 2023) | E28: 1 July 2023 - 15 March 2024 | F28: Y | G28: BNGU_excel.xlsx | H28: Y | I28: https://advance-lexis-com.ezproxy.library.tufts.edu/search/?pdmfid=1516831&crid=180415c0-8e43-4520-8653-869158ff96bf&pdpsf=&pdpost=&pdstartin=urn%3Ahlct%3A16&pdsearchterms=hlead(*water*+OR+river*+OR+lake+OR+dam+OR+stream+OR+tributary+OR+diversion+OR+irrigation+OR+pollution+OR+water+quality+OR+flood!+OR+drought!+OR+channel+OR+canal+OR+hydroelect!+OR+reservoir+OR+groundwater+OR+aquifer+OR+drought+OR+recharge+OR+%22water+table%22+OR+%22bore+hole%22)+and+hlead(treaty+OR+agree!+OR+negotiat!+OR+resolution+OR+commission+OR+secretariat+OR+joint+management+OR+basin+management+OR+peace+OR+accord+OR+%22peace+accord%22+OR+settle!+OR+cooperat!+OR+collaborat!+OR+disput!+OR+conflict!+OR+disagree!+OR+sanction!+OR+war+OR+troops+OR+%22letter+of+protest%22+OR+hostility+OR+%22shots+fired%22+OR+boycott+OR+protest!+OR+appeal+OR+intent+OR+reject+OR+threat!+OR+force+OR+coerce+OR+assault+OR+fight+OR+demand+OR+disapprove+OR+diploma!+OR+statement+OR+memorandum)+and+hlead(Bangau)+and+not+hlead(ocean+OR+navigat!+OR+nuclear+OR+%22water+cannon%22+OR+%22light+water+reactor%22+OR+%22mineral+water%22+OR+%22hold+water%22+OR+%22cold+water%22+OR+%22hot+water%22+OR+%22water+canister%22+OR+%22water+tight%22+OR+%22+water+down%22+OR+%22flood+of+refugees%22+OR+Rivera+OR+Suez+OR+Panama+OR+oil+OR+drugs+OR+%22three+gorges%22+OR+waterski+OR+watermelon+OR+dishwater+OR+waterproof+OR+%22water+resistant%22+OR+%22water+bath%22+)&pdsearchtype=SearchBox&pdtypeofsearch=searchboxclick&pdsf=&pdquerytemplateid=&pdtimeline=undefined%7Calldates&pdfromadvancedsearchpage=true&ecomp=xxLg9kk&earg=pdpsf&prid=23f3da92-673e-45a2-9b9e-22ed73f58158
A29: BNSA | B29: Oued Bou Namoussa | C29: Raunaq | D29: Y (1 July 2023) | E29: 1 July 2023 - 15 March 2024 | G29: No results | I29: https://advance-lexis-com.ezproxy.library.tufts.edu/search/?pdmfid=1516831&crid=41dc382b-a91d-42df-85a9-8090b5e4ac77&pdpsf=&pdpost=&pdstartin=urn%3Ahlct%3A16&pdsearchterms=hlead(*water*+OR+river*+OR+lake+OR+dam+OR+stream+OR+tributary+OR+diversion+OR+irrigation+OR+pollution+OR+water+quality+OR+flood!+OR+drought!+OR+channel+OR+canal+OR+hydroelect!+OR+reservoir+OR+groundwater+OR+aquifer+OR+drought+OR+recharge+OR+%22water+table%22+OR+%22bore+hole%22)+and+hlead(treaty+OR+agree!+OR+negotiat!+OR+resolution+OR+commission+OR+secretariat+OR+joint+management+OR+basin+management+OR+peace+OR+accord+OR+%22peace+accord%22+OR+settle!+OR+cooperat!+OR+collaborat!+OR+disput!+OR+conflict!+OR+disagree!+OR+sanction!+OR+war+OR+troops+OR+%22letter+of+protest%22+OR+hostility+OR+%22shots+fired%22+OR+boycott+OR+protest!+OR+appeal+OR+intent+OR+reject+OR+threat!+OR+force+OR+coerce+OR+assault+OR+fight+OR+demand+OR+disapprove+OR+diploma!+OR+statement+OR+memorandum)+and+hlead(Oued+Bou+Namoussa)+and+not+hlead(ocean+OR+navigat!+OR+nuclear+OR+%22water+cannon%22+OR+%22light+water+reactor%22+OR+%22mineral+water%22+OR+%22hold+water%22+OR+%22cold+water%22+OR+%22hot+water%22+OR+%22water+canister%22+OR+%22water+tight%22+OR+%22+water+down%22+OR+%22flood+of+refugees%22+OR+Rivera+OR+Suez+OR+Panama+OR+oil+OR+drugs+OR+%22three+gorges%22+OR+waterski+OR+watermelon+OR+dishwater+OR+waterproof+OR+%22water+resistant%22+OR+%22water+bath%22+)&pdsearchtype=SearchBox&pdtypeofsearch=searchboxclick&pdsf=&pdquerytemplateid=&pdtimeline=undefined%7Calldates&pdfromadvancedsearchpage=true&ecomp=xxLg9kk&earg=pdpsf&prid=23f3da92-673e-45a2-9b9e-22ed73f58158
A30: BRBY | B30: Berbyelva | C30: Raunaq | D30: Y (1 July 2023) | E30: 1 July 2023 - 15 March 2024 | G30: No results | I30: https://advance-lexis-com.ezproxy.library.tufts.edu/search/?pdmfid=1516831&crid=5cfdbf52-01c6-4ea6-a2f1-45a00a7aa495&pdpsf=&pdpost=&pdstartin=urn%3Ahlct%3A16&pdsearchterms=hlead(*water*+OR+river*+OR+lake+OR+dam+OR+stream+OR+tributary+OR+diversion+OR+irrigation+OR+pollution+OR+water+quality+OR+flood!+OR+drought!+OR+channel+OR+canal+OR+hydroelect!+OR+reservoir+OR+groundwater+OR+aquifer+OR+drought+OR+recharge+OR+%22water+table%22+OR+%22bore+hole%22)+and+hlead(treaty+OR+agree!+OR+negotiat!+OR+resolution+OR+commission+OR+secretariat+OR+joint+management+OR+basin+management+OR+peace+OR+accord+OR+%22peace+accord%22+OR+settle!+OR+cooperat!+OR+collaborat!+OR+disput!+OR+conflict!+OR+disagree!+OR+sanction!+OR+war+OR+troops+OR+%22letter+of+protest%22+OR+hostility+OR+%22shots+fired%22+OR+boycott+OR+protest!+OR+appeal+OR+intent+OR+reject+OR+threat!+OR+force+OR+coerce+OR+assault+OR+fight+OR+demand+OR+disapprove+OR+diploma!+OR+statement+OR+memorandum)+and+hlead(Berbyelva)+and+not+hlead(ocean+OR+navigat!+OR+nuclear+OR+%22water+cannon%22+OR+%22light+water+reactor%22+OR+%22mineral+water%22+OR+%22hold+water%22+OR+%22cold+water%22+OR+%22hot+water%22+OR+%22water+canister%22+OR+%22water+tight%22+OR+%22+water+down%22+OR+%22flood+of+refugees%22+OR+Rivera+OR+Suez+OR+Panama+OR+oil+OR+drugs+OR+%22three+gorges%22+OR+waterski+OR+watermelon+OR+dishwater+OR+waterproof+OR+%22water+resistant%22+OR+%22water+bath%22+)&pdsearchtype=SearchBox&pdtypeofsearch=searchboxclick&pdsf=&pdquerytemplateid=&pdtimeline=undefined%7Calldates&pdfromadvancedsearchpage=true&ecomp=xxLg9kk&earg=pdpsf&prid=23f3da92-673e-45a2-9b9e-22ed73f58158
